#VRML_SIM R2023b utf8

EXTERNPROTO "https://raw.githubusercontent.com/cyberbotics/webots/R2023b/projects/objects/backgrounds/protos/TexturedBackground.proto"
EXTERNPROTO "https://raw.githubusercontent.com/cyberbotics/webots/R2023b/projects/objects/backgrounds/protos/TexturedBackgroundLight.proto"
EXTERNPROTO "https://raw.githubusercontent.com/cyberbotics/webots/R2023b/projects/objects/floors/protos/Floor.proto"

WorldInfo {
  basicTimeStep 16
}
Viewpoint {
  orientation -0.3814756799166252 0.3814769820884979 0.8419926470990114 1.7419427510371475
  position -0.051069224941959646 -1.2227749221468025 1.3029737741226466
}
TexturedBackground {
}
TexturedBackgroundLight {
}
Floor {
  size 1 1
}
DEF WALL_1 Solid {
  translation 0.5 0 0.05
  children [
    DEF WALL_SHAPE Shape {
      appearance PBRAppearance {
        baseColor 0.12549 0.368627 0.729412
        roughness 1
        metalness 0
      }
      geometry Box {
        size 0.02 0.98 0.1
      }
    }
  ]
  boundingObject USE WALL_SHAPE
}
DEF WALL_2 Solid {
  translation -0.5 0 0.05
  children [
    USE WALL_SHAPE
  ]
  name "solid(1)"
  boundingObject USE WALL_SHAPE
}
DEF WALL_3 Solid {
  translation 0 -0.5 0.05
  rotation 0 0 1 1.5708
  children [
    USE WALL_SHAPE
  ]
  name "solid(2)"
  boundingObject USE WALL_SHAPE
}
DEF WALL_4 Solid {
  translation 0 0.5 0.05
  rotation 0 0 1 1.5708
  children [
    USE WALL_SHAPE
  ]
  name "solid(3)"
  boundingObject USE WALL_SHAPE
}
Robot {
  translation -0.14011996531532556 -0.059030399139380345 0.0398604896491437
  rotation 1.3501896210543249e-09 -4.359222271303096e-09 -1 2.540022182577084
  children [
    Camera {
      translation 0.08 0 0.034
      children [
        Pose {
          translation -0.015 0 0
          rotation -0.5770167337279206 -0.5780167627291821 0.5770167337279206 -2.09
          children [
            Shape {
              appearance PBRAppearance {
              }
              geometry Cylinder {
                height 0.03
                radius 0.01
              }
            }
          ]
        }
      ]
      locked TRUE
      fieldOfView 1.05
      width 80
      height 65
      antiAliasing TRUE
      noise 0.004
    }
    Accelerometer {
    }
    Compass {
    }
    Gyro {
    }
    Receiver {
      translation 0 0.5 0
    }
    GPS {
      translation 0 0 0.03
      children [
        Shape {
          geometry Cylinder {
            height 0.01
            radius 0.02
          }
        }
      ]
    }
    DEF BODY Shape {
      appearance PBRAppearance {
        baseColor 0.917647 0.145098 0.145098
        roughness 1
        metalness 0
      }
      geometry Box {
        size 0.2 0.1 0.05
      }
    }
    DEF WHEEL1 HingeJoint {
      jointParameters HingeJointParameters {
        position 1831.642341114971
        axis 0 1 0
        anchor 0.05 0.06 0
      }
      device [
        RotationalMotor {
          name "wheel1"
        }
      ]
      endPoint Solid {
        translation 0.05 0.06 0
        rotation 0.03317795954254486 -0.7067161926257495 0.7067187885440417 3.075261309596792
        children [
          DEF WHEEL Shape {
            appearance PBRAppearance {
              baseColor 0.305882 0.898039 0.25098
              roughness 1
              metalness 0
            }
            geometry Cylinder {
              height 0.02
              radius 0.04
              subdivision 24
            }
          }
        ]
        boundingObject USE WHEEL
        physics Physics {
        }
        linearVelocity -0.03297791463294994 -0.022637516886607777 1.367819255172338e-09
        angularVelocity 0.5659379230473247 -0.8244478560285085 1.1100363025788998e-09
      }
    }
    DEF WHEEL2 HingeJoint {
      jointParameters HingeJointParameters {
        position 2702.3861182181718
        axis 0 1 0
        anchor 0.05 -0.06 0
      }
      device [
        RotationalMotor {
          name "wheel2"
        }
      ]
      endPoint Solid {
        translation 0.05 -0.06 0
        rotation 0.911841762617037 0.2902963837602618 -0.2902974500803784 1.6629580651250042
        children [
          USE WHEEL
        ]
        name "solid(1)"
        boundingObject USE WHEEL
        physics Physics {
        }
        linearVelocity -0.0329779141312985 -0.022637516542184745 -1.3677434465345088e-09
        angularVelocity 0.5659379231078144 -0.824447855928121 1.0762381058319875e-09
      }
    }
    DEF WHEEL3 HingeJoint {
      jointParameters HingeJointParameters {
        position 1831.6424712492078
        axis 0 1 0
        anchor -0.05 0.06 0
      }
      device [
        RotationalMotor {
          name "wheel3"
        }
      ]
      endPoint Solid {
        translation -0.05 0.06 0
        rotation 0.03322399435060721 -0.7067151112891586 0.7067177072034796 3.0751693416947954
        children [
          USE WHEEL
        ]
        name "solid(2)"
        boundingObject USE WHEEL
        physics Physics {
        }
        linearVelocity -0.032977914346378534 -0.022637517304079213 1.3680444760418558e-09
        angularVelocity 0.5659379230551805 -0.8244478560231158 1.1082568393875905e-09
      }
    }
    DEF WHEEL4 HingeJoint {
      jointParameters HingeJointParameters {
        position 2702.386248461048
        axis 0 1 0
        anchor -0.05 -0.06 0
      }
      device [
        RotationalMotor {
          name "wheel4"
        }
      ]
      endPoint Solid {
        translation -0.05 -0.06 0
        rotation 0.9118071371780966 0.2903507579293158 -0.2903518244491599 1.6629958777019906
        children [
          USE WHEEL
        ]
        name "solid(3)"
        boundingObject USE WHEEL
        physics Physics {
        }
        linearVelocity -0.032977913844727286 -0.022637516959656555 -1.36751846441128e-09
        angularVelocity 0.5659379231156723 -0.8244478559227283 1.0744422471533826e-09
      }
    }
    DEF DS_RIGHT DistanceSensor {
      translation 0.1 -0.03 0
      rotation 0 0 1 -0.3
      children [
        Shape {
          appearance PBRAppearance {
            baseColor 0.184314 0.596078 0.847059
            roughness 1
            metalness 0
          }
          geometry Box {
            size 0.01 0.01 0.01
          }
        }
      ]
      name "ds_right"
    }
    DEF DS_LEFT DistanceSensor {
      translation 0.1 0.03 0
      rotation 0 0 1 0.3
      children [
        Shape {
          appearance PBRAppearance {
            baseColor 0.184314 0.596078 0.847059
            roughness 1
            metalness 0
          }
          geometry Box {
            size 0.01 0.01 0.01
          }
        }
      ]
      name "ds_left"
    }
  ]
  boundingObject USE BODY
  physics Physics {
    density -1
    mass 1
  }
  controller "four_wheels_collision_avoidance"
  linearVelocity -0.03297791423883852 -0.02263751692313179 1.5039845966824902e-13
  angularVelocity -1.9169012912809544e-08 -1.3161258521743505e-08 -7.424787536106164e-09
}
